[2024-08-09T08:40:50.638+0000] {local_task_job_runner.py:120} INFO - ::group::Pre task execution logs
[2024-08-09T08:40:50.742+0000] {taskinstance.py:2076} INFO - Dependencies all met for dep_context=non-requeueable deps ti=<TaskInstance: streaming_data.get_data manual__2024-08-09T08:40:48.161460+00:00 [queued]>
[2024-08-09T08:40:50.759+0000] {taskinstance.py:2076} INFO - Dependencies all met for dep_context=requeueable deps ti=<TaskInstance: streaming_data.get_data manual__2024-08-09T08:40:48.161460+00:00 [queued]>
[2024-08-09T08:40:50.760+0000] {taskinstance.py:2306} INFO - Starting attempt 1 of 2
[2024-08-09T08:40:50.794+0000] {taskinstance.py:2330} INFO - Executing <Task(PythonOperator): get_data> on 2024-08-09 08:40:48.161460+00:00
[2024-08-09T08:40:50.807+0000] {logging_mixin.py:188} WARNING - /home/***/.local/lib/python3.12/site-packages/***/task/task_runner/standard_task_runner.py:62 DeprecationWarning: This process (pid=560) is multi-threaded, use of fork() may lead to deadlocks in the child.
[2024-08-09T08:40:50.810+0000] {standard_task_runner.py:64} INFO - Started process 562 to run task
[2024-08-09T08:40:50.807+0000] {standard_task_runner.py:90} INFO - Running: ['***', 'tasks', 'run', 'streaming_data', 'get_data', 'manual__2024-08-09T08:40:48.161460+00:00', '--job-id', '163', '--raw', '--subdir', 'DAGS_FOLDER/stream.py', '--cfg-path', '/tmp/tmpf_xa5ecb']
[2024-08-09T08:40:50.812+0000] {standard_task_runner.py:91} INFO - Job 163: Subtask get_data
[2024-08-09T08:40:50.843+0000] {logging_mixin.py:188} WARNING - /home/***/.local/lib/python3.12/site-packages/***/settings.py:195 DeprecationWarning: The sql_alchemy_conn option in [core] has been moved to the sql_alchemy_conn option in [database] - the old setting has been used, but please update your config.
[2024-08-09T08:40:50.925+0000] {task_command.py:426} INFO - Running <TaskInstance: streaming_data.get_data manual__2024-08-09T08:40:48.161460+00:00 [running]> on host 562e157be0a0
[2024-08-09T08:40:51.157+0000] {taskinstance.py:2648} INFO - Exporting env vars: AIRFLOW_CTX_DAG_OWNER='***' AIRFLOW_CTX_DAG_ID='streaming_data' AIRFLOW_CTX_TASK_ID='get_data' AIRFLOW_CTX_EXECUTION_DATE='2024-08-09T08:40:48.161460+00:00' AIRFLOW_CTX_TRY_NUMBER='1' AIRFLOW_CTX_DAG_RUN_ID='manual__2024-08-09T08:40:48.161460+00:00'
[2024-08-09T08:40:51.159+0000] {taskinstance.py:430} INFO - ::endgroup::
[2024-08-09T08:40:51.191+0000] {taskinstance.py:441} INFO - ::group::Post task execution logs
[2024-08-09T08:40:51.192+0000] {taskinstance.py:2905} ERROR - Task failed with exception
Traceback (most recent call last):
  File "/home/airflow/.local/lib/python3.12/site-packages/airflow/models/taskinstance.py", line 465, in _execute_task
    result = _execute_callable(context=context, **execute_callable_kwargs)
             ^^^^^^^^^^^^^^^^^^^^^^^^^^^^^^^^^^^^^^^^^^^^^^^^^^^^^^^^^^^^^
  File "/home/airflow/.local/lib/python3.12/site-packages/airflow/models/taskinstance.py", line 432, in _execute_callable
    return execute_callable(context=context, **execute_callable_kwargs)
           ^^^^^^^^^^^^^^^^^^^^^^^^^^^^^^^^^^^^^^^^^^^^^^^^^^^^^^^^^^^^
  File "/home/airflow/.local/lib/python3.12/site-packages/airflow/models/baseoperator.py", line 401, in wrapper
    return func(self, *args, **kwargs)
           ^^^^^^^^^^^^^^^^^^^^^^^^^^^
  File "/home/airflow/.local/lib/python3.12/site-packages/airflow/operators/python.py", line 235, in execute
    return_value = self.execute_callable()
                   ^^^^^^^^^^^^^^^^^^^^^^^
  File "/home/airflow/.local/lib/python3.12/site-packages/airflow/operators/python.py", line 252, in execute_callable
    return self.python_callable(*self.op_args, **self.op_kwargs)
           ^^^^^^^^^^^^^^^^^^^^^^^^^^^^^^^^^^^^^^^^^^^^^^^^^^^^^
  File "/opt/airflow/dags/stream.py", line 41, in get_data
    yesterday = today - datetime.timedelta(days=1)
                        ^^^^^^^^^^^^^^^^^^
AttributeError: type object 'datetime.datetime' has no attribute 'timedelta'
[2024-08-09T08:40:51.225+0000] {taskinstance.py:1206} INFO - Marking task as UP_FOR_RETRY. dag_id=streaming_data, task_id=get_data, run_id=manual__2024-08-09T08:40:48.161460+00:00, execution_date=20240809T084048, start_date=20240809T084050, end_date=20240809T084051
[2024-08-09T08:40:51.258+0000] {standard_task_runner.py:110} ERROR - Failed to execute job 163 for task get_data (type object 'datetime.datetime' has no attribute 'timedelta'; 562)
[2024-08-09T08:40:51.307+0000] {local_task_job_runner.py:243} INFO - Task exited with return code 1
[2024-08-09T08:40:51.381+0000] {taskinstance.py:3503} INFO - 0 downstream tasks scheduled from follow-on schedule check
[2024-08-09T08:40:51.398+0000] {local_task_job_runner.py:222} INFO - ::endgroup::
